<?xml version="1.0"?>
<robot name="henes_t870">

  <material name="dark_grey">
    <color rgba="0.3 0.3 0.3 1.0"/>
  </material>
  <material name="black">
    <color rgba="0.1 0.1 0.1 1.0"/>
  </material>

  <link name="base_link">
    <visual>
      <geometry>
        <box size="1.4 0.775 0.531"/>
      </geometry>
      <material name="dark_grey"/>
    </visual>
    <collision>
      <geometry>
        <box size="1.4 0.775 0.531"/>
      </geometry>
    </collision>
  </link>

  <link name="front_left_wheel_link">
    <visual>
      <origin xyz="0 0 0" rpy="1.5707 0 0" />
      <geometry>
        <cylinder radius="0.115" length="0.12"/>
      </geometry>
      <material name="black"/>
    </visual>
    <collision>
      <origin xyz="0 0 0" rpy="1.5707 0 0" />
      <geometry>
        <cylinder radius="0.115" length="0.12"/>
      </geometry>
    </collision>
  </link>

  <link name="front_right_wheel_link">
    <visual>
      <origin xyz="0 0 0" rpy="1.5707 0 0" />
      <geometry>
        <cylinder radius="0.115" length="0.12"/>
      </geometry>
      <material name="black"/>
    </visual>
    <collision>
      <origin xyz="0 0 0" rpy="1.5707 0 0" />
      <geometry>
        <cylinder radius="0.115" length="0.12"/>
      </geometry>
    </collision>
  </link>

  <link name="rear_left_wheel_link">
    <visual>
      <origin xyz="0 0 0" rpy="1.5707 0 0" />
      <geometry>
        <cylinder radius="0.115" length="0.12"/>
      </geometry>
      <material name="black"/>
    </visual>
    <collision>
      <origin xyz="0 0 0" rpy="1.5707 0 0" />
      <geometry>
        <cylinder radius="0.115" length="0.12"/>
      </geometry>
    </collision>
  </link>

  <link name="rear_right_wheel_link">
    <visual>
      <origin xyz="0 0 0" rpy="1.5707 0 0" />
      <geometry>
        <cylinder radius="0.115" length="0.12"/>
      </geometry>
      <material name="black"/>
    </visual>
    <collision>
      <origin xyz="0 0 0" rpy="1.5707 0 0" />
      <geometry>
        <cylinder radius="0.115" length="0.12"/>
      </geometry>
    </collision>
  </link>

  <joint name="base_to_front_left_wheel_joint" type="continuous">
    <parent link="base_link"/>
    <child link="front_left_wheel_link"/>
    <origin xyz="0.45 0.43 -0.15" rpy="0 0 0"/>
    <axis xyz="0 1 0"/>
  </joint>

  <joint name="base_to_front_right_wheel_joint" type="continuous">
    <parent link="base_link"/>
    <child link="front_right_wheel_link"/>
    <origin xyz="0.45 -0.43 -0.15" rpy="0 0 0"/>
    <axis xyz="0 1 0"/>
  </joint>

  <joint name="base_to_rear_left_wheel_joint" type="continuous">
    <parent link="base_link"/>
    <child link="rear_left_wheel_link"/>
    <origin xyz="-0.45 0.43 -0.15" rpy="0 0 0"/>
    <axis xyz="0 1 0"/>
  </joint>

  <joint name="base_to_rear_right_wheel_joint" type="continuous">
    <parent link="base_link"/>
    <child link="rear_right_wheel_link"/>
    <origin xyz="-0.45 -0.43 -0.15" rpy="0 0 0"/>
    <axis xyz="0 1 0"/>
  </joint>

</robot>